Workbook

Sheet Schedule
A1: Address
A2: Project Start Date: | C2: 45985
A3: Task ID | B3: Task Name | C3: Duration (days) | D3: Pred Task ID | E3: Pred Type (FS/SS) | F3: Lag (days) | G3: Start | H3: Finish | I3: Status
A4: 1 | B4: Site cut & crossover gravel | C4: 1 | F4: 1 | G4: 46132 | H4: =IF(G4="","",WORKDAY(G4,C4-1)) -> 46132 | I4: Completed
A5: 2 | B5: House setout | C5: 1 | D5: 1 | E5: FS | F5: 0 | G5: =IF(D5="",$C$2,IF(E5="FS",WORKDAY(INDEX($H:$H,MATCH(D5,$A:$A,0)),F5+1),WORKDAY(INDEX($G:$G,MATCH(D5,$A:$A,0)),F5))) -> 46133 | H5: =IF(G5="","",WORKDAY(G5,C5-1)) -> 46133 | I5: Planning
A6: 3 | B6: Underground plumbing | C6: 3 | D6: 6 | E6: FS | F6: 0 | G6: =IF(D6="",$C$2,IF(E6="FS",WORKDAY(INDEX($H:$H,MATCH(D6,$A:$A,0)),F6+1),WORKDAY(INDEX($G:$G,MATCH(D6,$A:$A,0)),F6))) -> 46136 | H6: =IF(G6="","",WORKDAY(G6,C6-1)) -> 46140 | I6: Planning
A7: 4 | B7: Foundation materials delivery | C7: 1 | D7: 3 | E7: FS | F7: 0 | G7: =IF(D7="",$C$2,IF(E7="FS",WORKDAY(INDEX($H:$H,MATCH(D7,$A:$A,0)),F7+1),WORKDAY(INDEX($G:$G,MATCH(D7,$A:$A,0)),F7))) -> 46141 | H7: =IF(G7="","",WORKDAY(G7,C8-1)) -> 46141 | I7: Planning
A8: 5 | B8: Piers exacavation | C8: 1 | D8: 2 | E8: FS | F8: 0 | G8: =IF(D8="",$C$2,IF(E8="FS",WORKDAY(INDEX($H:$H,MATCH(D8,$A:$A,0)),F8+1),WORKDAY(INDEX($G:$G,MATCH(D8,$A:$A,0)),F8))) -> 46134 | H8: =IF(G8="","",WORKDAY(G8,C9-1)) -> 46134 | I8: Planning
A9: 6 | B9: Piers concrete pour | C9: 1 | D9: 5 | E9: FS | F9: 0 | G9: =IF(D9="",$C$2,IF(E9="FS",WORKDAY(INDEX($H:$H,MATCH(D9,$A:$A,0)),F9+1),WORKDAY(INDEX($G:$G,MATCH(D9,$A:$A,0)),F9))) -> 46135 | H9: =IF(G9="","",WORKDAY(G9,C10-1)) -> 46135 | I9: Planning
A10: 7 | B10: Piers engineering inspection | C10: 1 | D10: 6 | E10: SS | F10: 0 | G10: =IF(D10="",$C$2,IF(E10="FS",WORKDAY(INDEX($H:$H,MATCH(D10,$A:$A,0)),F10+1),WORKDAY(INDEX($G:$G,MATCH(D10,$A:$A,0)),F10))) -> 46135 | H10: =IF(G10="","",WORKDAY(G10,C11-1)) -> 46135 | I10: Planning
A11: 8 | B11: 4 slab pour | C11: 1 | D11: 9 | E11: FS | F11: 0 | G11: =G12+1 -> 46144 | H11: =IF(G11="","",WORKDAY(G11,C12-1)) -> 46144 | I11: Planning
A12: 9 | B12: 4 Slab prepare | C12: 1 | D12: 4 | E12: FS | F12: 1 | G12: =IF(D12="",$C$2,IF(E12="FS",WORKDAY(INDEX($H:$H,MATCH(D12,$A:$A,0)),F12+1),WORKDAY(INDEX($G:$G,MATCH(D12,$A:$A,0)),F12))) -> 46143 | H12: =IF(G12="","",WORKDAY(G12,C12-1)) -> 46143 | I12: Planning
A13: 10 | B13: 4 Termite | C13: 1 | D13: 9 | E13: SS | F13: 0 | G13: =IF(D13="",$C$2,IF(E13="FS",WORKDAY(INDEX($H:$H,MATCH(D13,$A:$A,0)),F13+1),WORKDAY(INDEX($G:$G,MATCH(D13,$A:$A,0)),F13))) -> 46143 | H13: =IF(G4="","",WORKDAY(G4,C4-1)) -> 46132 | I13: Planning
A14: 11 | B14: 4 engineering inspection | C14: 1 | D14: 9 | E14: FS | F14: -1 | G14: =IF(D14="",$C$2,IF(E14="FS",WORKDAY(INDEX($H:$H,MATCH(D14,$A:$A,0)),F14+1),WORKDAY(INDEX($G:$G,MATCH(D14,$A:$A,0)),F14))) -> 46143 | H14: =IF(G14="","",WORKDAY(G14,C14-1)) -> 46143 | I14: Planning
A15: 12 | B15: 4 termite under frames | C15: 1 | D15: 8 | E15: SS | F15: 1 | G15: =IF(D15="",$C$2,IF(E15="FS",WORKDAY(INDEX($H:$H,MATCH(D15,$A:$A,0)),F15+1),WORKDAY(INDEX($G:$G,MATCH(D15,$A:$A,0)),F15))) -> 46146 | H15: =IF(G15="","",WORKDAY(G15,C15-1)) -> 46146 | I15: Planning
A16: 13 | B16: 4 ground floor framing delivery | C16: 1 | D16: 77 | E16: FS | F16: 3 | G16: =IF(D16="",$C$2,IF(E16="FS",WORKDAY(INDEX($H:$H,MATCH(D16,$A:$A,0)),F16+1),WORKDAY(INDEX($G:$G,MATCH(D16,$A:$A,0)),F16))) -> 46150 | H16: =IF(G16="","",WORKDAY(G16,C16-1)) -> 46150 | I16: Planning
A17: 14 | B17: 4 ground floor framing | C17: 14 | D17: 13 | E17: FS | F17: 0 | G17: =IF(D17="",$C$2,IF(E17="FS",WORKDAY(INDEX($H:$H,MATCH(D17,$A:$A,0)),F17+1),WORKDAY(INDEX($G:$G,MATCH(D17,$A:$A,0)),F17))) -> 46153 | H17: =IF(G17="","",WORKDAY(G17,C17-1)) -> 46170 | I17: Planning
A18: 15 | C18: 0 | E18: FS | F18: 0 | G18: =IF(D18="",$C$2,IF(E18="FS",WORKDAY(INDEX($H:$H,MATCH(D18,$A:$A,0)),F18+1),WORKDAY(INDEX($G:$G,MATCH(D18,$A:$A,0)),F18))) -> 45985 | H18: =IF(G18="","",WORKDAY(G18,C18-1)) -> 45982 | I18: Planning
A19: 16 | C19: 0 | E19: FS | F19: 0 | G19: =IF(D19="",$C$2,IF(E19="FS",WORKDAY(INDEX($H:$H,MATCH(D19,$A:$A,0)),F19+1),WORKDAY(INDEX($G:$G,MATCH(D19,$A:$A,0)),F19))) -> 45985 | H19: =IF(G19="","",WORKDAY(G19,C19-1)) -> 45982 | I19: Planning
A20: 17 | B20: 4 midfloor materials delivery | C20: 1 | D20: 18 | E20: SS | F20: 0 | G20: =IF(D20="",$C$2,IF(E20="FS",WORKDAY(INDEX($H:$H,MATCH(D20,$A:$A,0)),F20+1),WORKDAY(INDEX($G:$G,MATCH(D20,$A:$A,0)),F20))) -> 46171 | H20: =IF(G20="","",WORKDAY(G20,C20-1)) -> 46171 | I20: Planning
A21: 18 | B21: 4 midfloor joists and nogging install | C21: 1 | D21: 14 | E21: FS | F21: 0 | G21: =IF(D21="",$C$2,IF(E21="FS",WORKDAY(INDEX($H:$H,MATCH(D21,$A:$A,0)),F21+1),WORKDAY(INDEX($G:$G,MATCH(D21,$A:$A,0)),F21))) -> 46171 | H21: =IF(G21="","",WORKDAY(G21,C21-1)) -> 46171 | I21: Planning
A22: 19 | B22: 4 midfloor flooring install | C22: 1 | D22: 17 | E22: FS | F22: 0 | G22: =IF(D22="",$C$2,IF(E22="FS",WORKDAY(INDEX($H:$H,MATCH(D22,$A:$A,0)),F22+1),WORKDAY(INDEX($G:$G,MATCH(D22,$A:$A,0)),F22))) -> 46174 | H22: =IF(G22="","",WORKDAY(G22,C22-1)) -> 46174 | I22: Planning
A23: 20 | B23: 4 upper framing&lower roof delivery | C23: 1 | D23: 19 | E23: SS | F23: 0 | G23: =IF(D23="",$C$2,IF(E23="FS",WORKDAY(INDEX($H:$H,MATCH(D23,$A:$A,0)),F23+1),WORKDAY(INDEX($G:$G,MATCH(D23,$A:$A,0)),F23))) -> 46174 | H23: =IF(G23="","",WORKDAY(G23,C23-1)) -> 46174 | I23: Planning
A24: 21 | B24: 4 upper framing install | C24: 2 | D24: 20 | E24: FS | F24: 0 | G24: =IF(D24="",$C$2,IF(E24="FS",WORKDAY(INDEX($H:$H,MATCH(D24,$A:$A,0)),F24+1),WORKDAY(INDEX($G:$G,MATCH(D24,$A:$A,0)),F24))) -> 46175 | H24: =IF(G24="","",WORKDAY(G24,C24-1)) -> 46176 | I24: Planning
A25: 22 | B25: 4 lower roof truss install | C25: 2 | D25: 21 | E25: FS | F25: 0 | G25: =IF(D25="",$C$2,IF(E25="FS",WORKDAY(INDEX($H:$H,MATCH(D25,$A:$A,0)),F25+1),WORKDAY(INDEX($G:$G,MATCH(D25,$A:$A,0)),F25))) -> 46177 | H25: =IF(G25="","",WORKDAY(G25,C25-1)) -> 46178 | I25: Planning
A26: 23 | B26: 4 lower roof edge protection ? | C26: 1 | D26: 22 | E26: FS | F26: 0 | G26: =IF(D26="",$C$2,IF(E26="FS",WORKDAY(INDEX($H:$H,MATCH(D26,$A:$A,0)),F26+1),WORKDAY(INDEX($G:$G,MATCH(D26,$A:$A,0)),F26))) -> 46181 | H26: =IF(G26="","",WORKDAY(G26,C26-1)) -> 46181 | I26: Planning
A27: 24 | B27: 4 lower roof install | C27: 5 | D27: 23 | E27: FS | F27: 0 | G27: =IF(D27="",$C$2,IF(E27="FS",WORKDAY(INDEX($H:$H,MATCH(D27,$A:$A,0)),F27+1),WORKDAY(INDEX($G:$G,MATCH(D27,$A:$A,0)),F27))) -> 46182 | H27: =IF(G27="","",WORKDAY(G27,C27-1)) -> 46188
A28: 25 | B28: 4 scaffolding up | C28: 2 | D28: 24 | E28: FS | F28: 0 | G28: =IF(D28="",$C$2,IF(E28="FS",WORKDAY(INDEX($H:$H,MATCH(D28,$A:$A,0)),F28+1),WORKDAY(INDEX($G:$G,MATCH(D28,$A:$A,0)),F28))) -> 46189 | H28: =IF(G28="","",WORKDAY(G28,C28-1)) -> 46190
A29: 26 | B29: 4 upper roof truss delivery | C29: 1 | D29: 25 | E29: SS | F29: 0 | G29: =IF(D29="",$C$2,IF(E29="FS",WORKDAY(INDEX($H:$H,MATCH(D29,$A:$A,0)),F29+1),WORKDAY(INDEX($G:$G,MATCH(D29,$A:$A,0)),F29))) -> 46189 | H29: =IF(G29="","",WORKDAY(G29,C29-1)) -> 46189
A30: 27 | B30: 4 upper roof truss install | C30: 2 | D30: 26 | E30: FS | F30: 0 | G30: =IF(D30="",$C$2,IF(E30="FS",WORKDAY(INDEX($H:$H,MATCH(D30,$A:$A,0)),F30+1),WORKDAY(INDEX($G:$G,MATCH(D30,$A:$A,0)),F30))) -> 46190 | H30: =IF(G30="","",WORKDAY(G30,C30-1)) -> 46191
A31: 28 | B31: 4 upper roof edge protection （not required?) | C31: 0 | D31: 27 | E31: FS | F31: 0 | G31: =IF(D31="",$C$2,IF(E31="FS",WORKDAY(INDEX($H:$H,MATCH(D31,$A:$A,0)),F31+1),WORKDAY(INDEX($G:$G,MATCH(D31,$A:$A,0)),F31))) -> 46192 | H31: =IF(G31="","",WORKDAY(G31,C31-1)) -> 46191
A32: 29 | B32: 4 upper roof install | C32: 14 | D32: 28 | E32: FS | F32: 0 | G32: =IF(D32="",$C$2,IF(E32="FS",WORKDAY(INDEX($H:$H,MATCH(D32,$A:$A,0)),F32+1),WORKDAY(INDEX($G:$G,MATCH(D32,$A:$A,0)),F32))) -> 46192 | H32: =IF(G32="","",WORKDAY(G32,C32-1)) -> 46211
A33: 30 | B33: 4 electrical roughin | C33: 2 | D33: 29 | E33: FS | F33: 0 | G33: =IF(D33="",$C$2,IF(E33="FS",WORKDAY(INDEX($H:$H,MATCH(D33,$A:$A,0)),F33+1),WORKDAY(INDEX($G:$G,MATCH(D33,$A:$A,0)),F33))) -> 46212 | H33: =IF(G33="","",WORKDAY(G33,C33-1)) -> 46213
A34: 31 | B34: 4 AC roughin | C34: 2 | D34: 29 | E34: FS | F34: 0 | G34: =IF(D34="",$C$2,IF(E34="FS",WORKDAY(INDEX($H:$H,MATCH(D34,$A:$A,0)),F34+1),WORKDAY(INDEX($G:$G,MATCH(D34,$A:$A,0)),F34))) -> 46212 | H34: =IF(G34="","",WORKDAY(G34,C34-1)) -> 46213
A35: 32 | B35: 4 plumbing roughin | C35: 2 | D35: 30 | E35: FS | F35: 0 | G35: =IF(D35="",$C$2,IF(E35="FS",WORKDAY(INDEX($H:$H,MATCH(D35,$A:$A,0)),F35+1),WORKDAY(INDEX($G:$G,MATCH(D35,$A:$A,0)),F35))) -> 46216 | H35: =IF(G35="","",WORKDAY(G35,C35-1)) -> 46217
A36: 33 | B36: 4 wall wrap | C36: 1 | D36: 27 | E36: FS | F36: 0 | G36: =IF(D36="",$C$2,IF(E36="FS",WORKDAY(INDEX($H:$H,MATCH(D36,$A:$A,0)),F36+1),WORKDAY(INDEX($G:$G,MATCH(D36,$A:$A,0)),F36))) -> 46192 | H36: =IF(G36="","",WORKDAY(G36,C36-1)) -> 46192
A37: 34 | B37: 4 framing inspection | C37: 1 | D37: 27 | E37: FS | F37: 0 | G37: =IF(D37="",$C$2,IF(E37="FS",WORKDAY(INDEX($H:$H,MATCH(D37,$A:$A,0)),F37+1),WORKDAY(INDEX($G:$G,MATCH(D37,$A:$A,0)),F37))) -> 46192 | H37: =IF(G37="","",WORKDAY(G37,C37-1)) -> 46192
A38: 35 | B38: 4 windows delivery | C38: 1 | D38: 29 | E38: FS | F38: -1 | G38: =IF(D38="",$C$2,IF(E38="FS",WORKDAY(INDEX($H:$H,MATCH(D38,$A:$A,0)),F38+1),WORKDAY(INDEX($G:$G,MATCH(D38,$A:$A,0)),F38))) -> 46211 | H38: =IF(G38="","",WORKDAY(G38,C38-1)) -> 46211
A39: 36 | B39: 4 entry doors delivery | C39: 1 | D39: 29 | E39: FS | F39: -1 | G39: =IF(D39="",$C$2,IF(E39="FS",WORKDAY(INDEX($H:$H,MATCH(D39,$A:$A,0)),F39+1),WORKDAY(INDEX($G:$G,MATCH(D39,$A:$A,0)),F39))) -> 46211 | H39: =IF(G39="","",WORKDAY(G39,C39-1)) -> 46211 | J39: Entry door TBA
A40: 37 | B40: 4 lockup labour | C40: 1 | D40: 29 | E40: FS | F40: 0 | G40: =IF(D40="",$C$2,IF(E40="FS",WORKDAY(INDEX($H:$H,MATCH(D40,$A:$A,0)),F40+1),WORKDAY(INDEX($G:$G,MATCH(D40,$A:$A,0)),F40))) -> 46212 | H40: =IF(G40="","",WORKDAY(G40,C40-1)) -> 46212
...

Sheet Gantt
A1: Gantt View (linked to Schedule) | C1: =IF(C2="","",TEXT(C2,"d-mmm")) -> 24-Nov | D1: =IF(D2="","",TEXT(D2,"d-mmm")) -> 25-Nov | E1: =IF(E2="","",TEXT(E2,"d-mmm")) -> 26-Nov | F1: =IF(F2="","",TEXT(F2,"d-mmm")) -> 27-Nov | G1: =IF(G2="","",TEXT(G2,"d-mmm")) -> 28-Nov | H1: =IF(H2="","",TEXT(H2,"d-mmm")) -> 29-Nov | I1: =IF(I2="","",TEXT(I2,"d-mmm")) -> 30-Nov | J1: =IF(J2="","",TEXT(J2,"d-mmm")) -> 1-Dec | ... EZ1: =IF(EZ2="","",TEXT(EZ2,"d-mmm")) -> 26-Apr
A2: Task ID | B2: Task Name | C2: =IF(Schedule!$C$2="","",Schedule!$C$2) -> 45985 | D2: =IF(C2="","",C2+1) -> 45986 | E2: =IF(D2="","",D2+1) -> 45987 | F2: =IF(E2="","",E2+1) -> 45988 | G2: =IF(F2="","",F2+1) -> 45989 | H2: =IF(G2="","",G2+1) -> 45990 | I2: =IF(H2="","",H2+1) -> 45991 | J2: =IF(I2="","",I2+1) -> 45992 | K2: =IF(J2="","",J2+1) -> 45993 | ... EZ2: =IF(EY2="","",EY2+1) -> 46138
A3: =Schedule!A4 -> 1 | B3: =Schedule!B4 -> Site cut & crossover gravel | C3: =IF(C2="","",IF(AND(C2>=Schedule!$G4,C2<=Schedule!$H4),"■","")) | D3: =IF(D2="","",IF(AND(D2>=Schedule!$G4,D2<=Schedule!$H4),"■","")) | E3: =IF(E2="","",IF(AND(E2>=Schedule!$G4,E2<=Schedule!$H4),"■","")) | F3: =IF(F2="","",IF(AND(F2>=Schedule!$G4,F2<=Schedule!$H4),"■","")) | G3: =IF(G2="","",IF(AND(G2>=Schedule!$G4,G2<=Schedule!$H4),"■","")) | H3: =IF(H2="","",IF(AND(H2>=Schedule!$G4,H2<=Schedule!$H4),"■","")) | I3: =IF(I2="","",IF(AND(I2>=Schedule!$G4,I2<=Schedule!$H4),"■","")) | J3: =IF(J2="","",IF(AND(J2>=Schedule!$G4,J2<=Schedule!$H4),"■","")) | ... EZ3: =IF(EZ2="","",IF(AND(EZ2>=Schedule!$G4,EZ2<=Schedule!$H4),"■",""))
A4: =Schedule!A5 -> 2 | B4: =Schedule!B5 -> House setout | C4: =IF(C2="","",IF(AND(C2>=Schedule!$G5,C2<=Schedule!$H5),"■","")) | D4: =IF(D2="","",IF(AND(D2>=Schedule!$G5,D2<=Schedule!$H5),"■","")) | E4: =IF(E2="","",IF(AND(E2>=Schedule!$G5,E2<=Schedule!$H5),"■","")) | F4: =IF(F2="","",IF(AND(F2>=Schedule!$G5,F2<=Schedule!$H5),"■","")) | G4: =IF(G2="","",IF(AND(G2>=Schedule!$G5,G2<=Schedule!$H5),"■","")) | H4: =IF(H2="","",IF(AND(H2>=Schedule!$G5,H2<=Schedule!$H5),"■","")) | I4: =IF(I2="","",IF(AND(I2>=Schedule!$G5,I2<=Schedule!$H5),"■","")) | J4: =IF(J2="","",IF(AND(J2>=Schedule!$G5,J2<=Schedule!$H5),"■","")) | ... EZ4: =IF(EZ2="","",IF(AND(EZ2>=Schedule!$G5,EZ2<=Schedule!$H5),"■",""))
A5: =Schedule!A6 -> 3 | B5: =Schedule!B6 -> Underground plumbing | C5: =IF(C2="","",IF(AND(C2>=Schedule!$G6,C2<=Schedule!$H6),"■","")) | D5: =IF(D2="","",IF(AND(D2>=Schedule!$G6,D2<=Schedule!$H6),"■","")) | E5: =IF(E2="","",IF(AND(E2>=Schedule!$G6,E2<=Schedule!$H6),"■","")) | F5: =IF(F2="","",IF(AND(F2>=Schedule!$G6,F2<=Schedule!$H6),"■","")) | G5: =IF(G2="","",IF(AND(G2>=Schedule!$G6,G2<=Schedule!$H6),"■","")) | H5: =IF(H2="","",IF(AND(H2>=Schedule!$G6,H2<=Schedule!$H6),"■","")) | I5: =IF(I2="","",IF(AND(I2>=Schedule!$G6,I2<=Schedule!$H6),"■","")) | J5: =IF(J2="","",IF(AND(J2>=Schedule!$G6,J2<=Schedule!$H6),"■","")) | ... EZ5: =IF(EZ2="","",IF(AND(EZ2>=Schedule!$G6,EZ2<=Schedule!$H6),"■","")) -> ■
A6: =Schedule!A7 -> 4 | B6: =Schedule!B7 -> Foundation materials delivery | C6: =IF(C2="","",IF(AND(C2>=Schedule!$G7,C2<=Schedule!$H7),"■","")) | D6: =IF(D2="","",IF(AND(D2>=Schedule!$G7,D2<=Schedule!$H7),"■","")) | E6: =IF(E2="","",IF(AND(E2>=Schedule!$G7,E2<=Schedule!$H7),"■","")) | F6: =IF(F2="","",IF(AND(F2>=Schedule!$G7,F2<=Schedule!$H7),"■","")) | G6: =IF(G2="","",IF(AND(G2>=Schedule!$G7,G2<=Schedule!$H7),"■","")) | H6: =IF(H2="","",IF(AND(H2>=Schedule!$G7,H2<=Schedule!$H7),"■","")) | I6: =IF(I2="","",IF(AND(I2>=Schedule!$G7,I2<=Schedule!$H7),"■","")) | J6: =IF(J2="","",IF(AND(J2>=Schedule!$G7,J2<=Schedule!$H7),"■","")) | ... EZ6: =IF(EZ2="","",IF(AND(EZ2>=Schedule!$G7,EZ2<=Schedule!$H7),"■",""))
A7: =Schedule!A8 -> 5 | B7: =Schedule!B8 -> Piers exacavation | C7: =IF(C2="","",IF(AND(C2>=Schedule!$G8,C2<=Schedule!$H8),"■","")) | D7: =IF(D2="","",IF(AND(D2>=Schedule!$G8,D2<=Schedule!$H8),"■","")) | E7: =IF(E2="","",IF(AND(E2>=Schedule!$G8,E2<=Schedule!$H8),"■","")) | F7: =IF(F2="","",IF(AND(F2>=Schedule!$G8,F2<=Schedule!$H8),"■","")) | G7: =IF(G2="","",IF(AND(G2>=Schedule!$G8,G2<=Schedule!$H8),"■","")) | H7: =IF(H2="","",IF(AND(H2>=Schedule!$G8,H2<=Schedule!$H8),"■","")) | I7: =IF(I2="","",IF(AND(I2>=Schedule!$G8,I2<=Schedule!$H8),"■","")) | J7: =IF(J2="","",IF(AND(J2>=Schedule!$G8,J2<=Schedule!$H8),"■","")) | ... EZ7: =IF(EZ2="","",IF(AND(EZ2>=Schedule!$G8,EZ2<=Schedule!$H8),"■",""))
A8: =Schedule!A9 -> 6 | B8: =Schedule!B9 -> Piers concrete pour | C8: =IF(C2="","",IF(AND(C2>=Schedule!$G9,C2<=Schedule!$H9),"■","")) | D8: =IF(D2="","",IF(AND(D2>=Schedule!$G9,D2<=Schedule!$H9),"■","")) | E8: =IF(E2="","",IF(AND(E2>=Schedule!$G9,E2<=Schedule!$H9),"■","")) | F8: =IF(F2="","",IF(AND(F2>=Schedule!$G9,F2<=Schedule!$H9),"■","")) | G8: =IF(G2="","",IF(AND(G2>=Schedule!$G9,G2<=Schedule!$H9),"■","")) | H8: =IF(H2="","",IF(AND(H2>=Schedule!$G9,H2<=Schedule!$H9),"■","")) | I8: =IF(I2="","",IF(AND(I2>=Schedule!$G9,I2<=Schedule!$H9),"■","")) | J8: =IF(J2="","",IF(AND(J2>=Schedule!$G9,J2<=Schedule!$H9),"■","")) | ... EZ8: =IF(EZ2="","",IF(AND(EZ2>=Schedule!$G9,EZ2<=Schedule!$H9),"■",""))
A9: =Schedule!A10 -> 7 | B9: =Schedule!B10 -> Piers engineering inspection | C9: =IF(C2="","",IF(AND(C2>=Schedule!$G10,C2<=Schedule!$H10),"■","")) | D9: =IF(D2="","",IF(AND(D2>=Schedule!$G10,D2<=Schedule!$H10),"■","")) | E9: =IF(E2="","",IF(AND(E2>=Schedule!$G10,E2<=Schedule!$H10),"■","")) | F9: =IF(F2="","",IF(AND(F2>=Schedule!$G10,F2<=Schedule!$H10),"■","")) | G9: =IF(G2="","",IF(AND(G2>=Schedule!$G10,G2<=Schedule!$H10),"■","")) | H9: =IF(H2="","",IF(AND(H2>=Schedule!$G10,H2<=Schedule!$H10),"■","")) | I9: =IF(I2="","",IF(AND(I2>=Schedule!$G10,I2<=Schedule!$H10),"■","")) | J9: =IF(J2="","",IF(AND(J2>=Schedule!$G10,J2<=Schedule!$H10),"■","")) | ... EZ9: =IF(EZ2="","",IF(AND(EZ2>=Schedule!$G10,EZ2<=Schedule!$H10),"■",""))
A10: =Schedule!A11 -> 8 | B10: =Schedule!B11 -> 4 slab pour | C10: =IF(C2="","",IF(AND(C2>=Schedule!$G11,C2<=Schedule!$H11),"■","")) | D10: =IF(D2="","",IF(AND(D2>=Schedule!$G11,D2<=Schedule!$H11),"■","")) | E10: =IF(E2="","",IF(AND(E2>=Schedule!$G11,E2<=Schedule!$H11),"■","")) | F10: =IF(F2="","",IF(AND(F2>=Schedule!$G11,F2<=Schedule!$H11),"■","")) | G10: =IF(G2="","",IF(AND(G2>=Schedule!$G11,G2<=Schedule!$H11),"■","")) | H10: =IF(H2="","",IF(AND(H2>=Schedule!$G11,H2<=Schedule!$H11),"■","")) | I10: =IF(I2="","",IF(AND(I2>=Schedule!$G11,I2<=Schedule!$H11),"■","")) | J10: =IF(J2="","",IF(AND(J2>=Schedule!$G11,J2<=Schedule!$H11),"■","")) | ... EZ10: =IF(EZ2="","",IF(AND(EZ2>=Schedule!$G11,EZ2<=Schedule!$H11),"■",""))
A11: =Schedule!A12 -> 9 | B11: =Schedule!B12 -> 4 Slab prepare | C11: =IF(C2="","",IF(AND(C2>=Schedule!$G12,C2<=Schedule!$H12),"■","")) | D11: =IF(D2="","",IF(AND(D2>=Schedule!$G12,D2<=Schedule!$H12),"■","")) | E11: =IF(E2="","",IF(AND(E2>=Schedule!$G12,E2<=Schedule!$H12),"■","")) | F11: =IF(F2="","",IF(AND(F2>=Schedule!$G12,F2<=Schedule!$H12),"■","")) | G11: =IF(G2="","",IF(AND(G2>=Schedule!$G12,G2<=Schedule!$H12),"■","")) | H11: =IF(H2="","",IF(AND(H2>=Schedule!$G12,H2<=Schedule!$H12),"■","")) | I11: =IF(I2="","",IF(AND(I2>=Schedule!$G12,I2<=Schedule!$H12),"■","")) | J11: =IF(J2="","",IF(AND(J2>=Schedule!$G12,J2<=Schedule!$H12),"■","")) | ... EZ11: =IF(EZ2="","",IF(AND(EZ2>=Schedule!$G12,EZ2<=Schedule!$H12),"■",""))
A12: =Schedule!A13 -> 10 | B12: =Schedule!B13 -> 4 Termite | C12: =IF(C2="","",IF(AND(C2>=Schedule!$G13,C2<=Schedule!$H13),"■","")) | D12: =IF(D2="","",IF(AND(D2>=Schedule!$G13,D2<=Schedule!$H13),"■","")) | E12: =IF(E2="","",IF(AND(E2>=Schedule!$G13,E2<=Schedule!$H13),"■","")) | F12: =IF(F2="","",IF(AND(F2>=Schedule!$G13,F2<=Schedule!$H13),"■","")) | G12: =IF(G2="","",IF(AND(G2>=Schedule!$G13,G2<=Schedule!$H13),"■","")) | H12: =IF(H2="","",IF(AND(H2>=Schedule!$G13,H2<=Schedule!$H13),"■","")) | I12: =IF(I2="","",IF(AND(I2>=Schedule!$G13,I2<=Schedule!$H13),"■","")) | J12: =IF(J2="","",IF(AND(J2>=Schedule!$G13,J2<=Schedule!$H13),"■","")) | ... EZ12: =IF(EZ2="","",IF(AND(EZ2>=Schedule!$G13,EZ2<=Schedule!$H13),"■",""))
A13: =Schedule!A14 -> 11 | B13: =Schedule!B14 -> 4 engineering inspection | C13: =IF(C2="","",IF(AND(C2>=Schedule!$G14,C2<=Schedule!$H14),"■","")) | D13: =IF(D2="","",IF(AND(D2>=Schedule!$G14,D2<=Schedule!$H14),"■","")) | E13: =IF(E2="","",IF(AND(E2>=Schedule!$G14,E2<=Schedule!$H14),"■","")) | F13: =IF(F2="","",IF(AND(F2>=Schedule!$G14,F2<=Schedule!$H14),"■","")) | G13: =IF(G2="","",IF(AND(G2>=Schedule!$G14,G2<=Schedule!$H14),"■","")) | H13: =IF(H2="","",IF(AND(H2>=Schedule!$G14,H2<=Schedule!$H14),"■","")) | I13: =IF(I2="","",IF(AND(I2>=Schedule!$G14,I2<=Schedule!$H14),"■","")) | J13: =IF(J2="","",IF(AND(J2>=Schedule!$G14,J2<=Schedule!$H14),"■","")) | ... EZ13: =IF(EZ2="","",IF(AND(EZ2>=Schedule!$G14,EZ2<=Schedule!$H14),"■",""))
A14: =Schedule!A15 -> 12 | B14: =Schedule!B15 -> 4 termite under frames | C14: =IF(C2="","",IF(AND(C2>=Schedule!$G15,C2<=Schedule!$H15),"■","")) | D14: =IF(D2="","",IF(AND(D2>=Schedule!$G15,D2<=Schedule!$H15),"■","")) | E14: =IF(E2="","",IF(AND(E2>=Schedule!$G15,E2<=Schedule!$H15),"■","")) | F14: =IF(F2="","",IF(AND(F2>=Schedule!$G15,F2<=Schedule!$H15),"■","")) | G14: =IF(G2="","",IF(AND(G2>=Schedule!$G15,G2<=Schedule!$H15),"■","")) | H14: =IF(H2="","",IF(AND(H2>=Schedule!$G15,H2<=Schedule!$H15),"■","")) | I14: =IF(I2="","",IF(AND(I2>=Schedule!$G15,I2<=Schedule!$H15),"■","")) | J14: =IF(J2="","",IF(AND(J2>=Schedule!$G15,J2<=Schedule!$H15),"■","")) | ... EZ14: =IF(EZ2="","",IF(AND(EZ2>=Schedule!$G15,EZ2<=Schedule!$H15),"■",""))
A15: =Schedule!A16 -> 13 | B15: =Schedule!B16 -> 4 ground floor framing delivery | C15: =IF(C2="","",IF(AND(C2>=Schedule!$G16,C2<=Schedule!$H16),"■","")) | D15: =IF(D2="","",IF(AND(D2>=Schedule!$G16,D2<=Schedule!$H16),"■","")) | E15: =IF(E2="","",IF(AND(E2>=Schedule!$G16,E2<=Schedule!$H16),"■","")) | F15: =IF(F2="","",IF(AND(F2>=Schedule!$G16,F2<=Schedule!$H16),"■","")) | G15: =IF(G2="","",IF(AND(G2>=Schedule!$G16,G2<=Schedule!$H16),"■","")) | H15: =IF(H2="","",IF(AND(H2>=Schedule!$G16,H2<=Schedule!$H16),"■","")) | I15: =IF(I2="","",IF(AND(I2>=Schedule!$G16,I2<=Schedule!$H16),"■","")) | J15: =IF(J2="","",IF(AND(J2>=Schedule!$G16,J2<=Schedule!$H16),"■","")) | ... EZ15: =IF(EZ2="","",IF(AND(EZ2>=Schedule!$G16,EZ2<=Schedule!$H16),"■",""))
A16: =Schedule!A17 -> 14 | B16: =Schedule!B17 -> 4 ground floor framing | C16: =IF(C2="","",IF(AND(C2>=Schedule!$G17,C2<=Schedule!$H17),"■","")) | D16: =IF(D2="","",IF(AND(D2>=Schedule!$G17,D2<=Schedule!$H17),"■","")) | E16: =IF(E2="","",IF(AND(E2>=Schedule!$G17,E2<=Schedule!$H17),"■","")) | F16: =IF(F2="","",IF(AND(F2>=Schedule!$G17,F2<=Schedule!$H17),"■","")) | G16: =IF(G2="","",IF(AND(G2>=Schedule!$G17,G2<=Schedule!$H17),"■","")) | H16: =IF(H2="","",IF(AND(H2>=Schedule!$G17,H2<=Schedule!$H17),"■","")) | I16: =IF(I2="","",IF(AND(I2>=Schedule!$G17,I2<=Schedule!$H17),"■","")) | J16: =IF(J2="","",IF(AND(J2>=Schedule!$G17,J2<=Schedule!$H17),"■","")) | ... EZ16: =IF(EZ2="","",IF(AND(EZ2>=Schedule!$G17,EZ2<=Schedule!$H17),"■",""))
A17: =Schedule!A18 -> 15 | B17: =Schedule!B18 -> 0 | C17: =IF(C2="","",IF(AND(C2>=Schedule!$G18,C2<=Schedule!$H18),"■","")) | D17: =IF(D2="","",IF(AND(D2>=Schedule!$G18,D2<=Schedule!$H18),"■","")) | E17: =IF(E2="","",IF(AND(E2>=Schedule!$G18,E2<=Schedule!$H18),"■","")) | F17: =IF(F2="","",IF(AND(F2>=Schedule!$G18,F2<=Schedule!$H18),"■","")) | G17: =IF(G2="","",IF(AND(G2>=Schedule!$G18,G2<=Schedule!$H18),"■","")) | H17: =IF(H2="","",IF(AND(H2>=Schedule!$G18,H2<=Schedule!$H18),"■","")) | I17: =IF(I2="","",IF(AND(I2>=Schedule!$G18,I2<=Schedule!$H18),"■","")) | J17: =IF(J2="","",IF(AND(J2>=Schedule!$G18,J2<=Schedule!$H18),"■","")) | ... EZ17: =IF(EZ2="","",IF(AND(EZ2>=Schedule!$G18,EZ2<=Schedule!$H18),"■",""))
A18: =Schedule!A19 -> 16 | B18: =Schedule!B19 -> 0 | C18: =IF(C2="","",IF(AND(C2>=Schedule!$G19,C2<=Schedule!$H19),"■","")) | D18: =IF(D2="","",IF(AND(D2>=Schedule!$G19,D2<=Schedule!$H19),"■","")) | E18: =IF(E2="","",IF(AND(E2>=Schedule!$G19,E2<=Schedule!$H19),"■","")) | F18: =IF(F2="","",IF(AND(F2>=Schedule!$G19,F2<=Schedule!$H19),"■","")) | G18: =IF(G2="","",IF(AND(G2>=Schedule!$G19,G2<=Schedule!$H19),"■","")) | H18: =IF(H2="","",IF(AND(H2>=Schedule!$G19,H2<=Schedule!$H19),"■","")) | I18: =IF(I2="","",IF(AND(I2>=Schedule!$G19,I2<=Schedule!$H19),"■","")) | J18: =IF(J2="","",IF(AND(J2>=Schedule!$G19,J2<=Schedule!$H19),"■","")) | ... EZ18: =IF(EZ2="","",IF(AND(EZ2>=Schedule!$G19,EZ2<=Schedule!$H19),"■",""))
A19: =Schedule!A20 -> 17 | B19: =Schedule!B20 -> 4 midfloor materials delivery | C19: =IF(C2="","",IF(AND(C2>=Schedule!$G20,C2<=Schedule!$H20),"■","")) | D19: =IF(D2="","",IF(AND(D2>=Schedule!$G20,D2<=Schedule!$H20),"■","")) | E19: =IF(E2="","",IF(AND(E2>=Schedule!$G20,E2<=Schedule!$H20),"■","")) | F19: =IF(F2="","",IF(AND(F2>=Schedule!$G20,F2<=Schedule!$H20),"■","")) | G19: =IF(G2="","",IF(AND(G2>=Schedule!$G20,G2<=Schedule!$H20),"■","")) | H19: =IF(H2="","",IF(AND(H2>=Schedule!$G20,H2<=Schedule!$H20),"■","")) | I19: =IF(I2="","",IF(AND(I2>=Schedule!$G20,I2<=Schedule!$H20),"■","")) | J19: =IF(J2="","",IF(AND(J2>=Schedule!$G20,J2<=Schedule!$H20),"■","")) | ... EZ19: =IF(EZ2="","",IF(AND(EZ2>=Schedule!$G20,EZ2<=Schedule!$H20),"■",""))
A20: =Schedule!A21 -> 18 | B20: =Schedule!B21 -> 4 midfloor joists and nogging install | C20: =IF(C2="","",IF(AND(C2>=Schedule!$G21,C2<=Schedule!$H21),"■","")) | D20: =IF(D2="","",IF(AND(D2>=Schedule!$G21,D2<=Schedule!$H21),"■","")) | E20: =IF(E2="","",IF(AND(E2>=Schedule!$G21,E2<=Schedule!$H21),"■","")) | F20: =IF(F2="","",IF(AND(F2>=Schedule!$G21,F2<=Schedule!$H21),"■","")) | G20: =IF(G2="","",IF(AND(G2>=Schedule!$G21,G2<=Schedule!$H21),"■","")) | H20: =IF(H2="","",IF(AND(H2>=Schedule!$G21,H2<=Schedule!$H21),"■","")) | I20: =IF(I2="","",IF(AND(I2>=Schedule!$G21,I2<=Schedule!$H21),"■","")) | J20: =IF(J2="","",IF(AND(J2>=Schedule!$G21,J2<=Schedule!$H21),"■","")) | ... EZ20: =IF(EZ2="","",IF(AND(EZ2>=Schedule!$G21,EZ2<=Schedule!$H21),"■",""))
A21: =Schedule!A22 -> 19 | B21: =Schedule!B22 -> 4 midfloor flooring install | C21: =IF(C2="","",IF(AND(C2>=Schedule!$G22,C2<=Schedule!$H22),"■","")) | D21: =IF(D2="","",IF(AND(D2>=Schedule!$G22,D2<=Schedule!$H22),"■","")) | E21: =IF(E2="","",IF(AND(E2>=Schedule!$G22,E2<=Schedule!$H22),"■","")) | F21: =IF(F2="","",IF(AND(F2>=Schedule!$G22,F2<=Schedule!$H22),"■","")) | G21: =IF(G2="","",IF(AND(G2>=Schedule!$G22,G2<=Schedule!$H22),"■","")) | H21: =IF(H2="","",IF(AND(H2>=Schedule!$G22,H2<=Schedule!$H22),"■","")) | I21: =IF(I2="","",IF(AND(I2>=Schedule!$G22,I2<=Schedule!$H22),"■","")) | J21: =IF(J2="","",IF(AND(J2>=Schedule!$G22,J2<=Schedule!$H22),"■","")) | ... EZ21: =IF(EZ2="","",IF(AND(EZ2>=Schedule!$G22,EZ2<=Schedule!$H22),"■",""))
A22: =Schedule!A23 -> 20 | B22: =Schedule!B23 -> 4 upper framing&lower roof delivery | C22: =IF(C2="","",IF(AND(C2>=Schedule!$G23,C2<=Schedule!$H23),"■","")) | D22: =IF(D2="","",IF(AND(D2>=Schedule!$G23,D2<=Schedule!$H23),"■","")) | E22: =IF(E2="","",IF(AND(E2>=Schedule!$G23,E2<=Schedule!$H23),"■","")) | F22: =IF(F2="","",IF(AND(F2>=Schedule!$G23,F2<=Schedule!$H23),"■","")) | G22: =IF(G2="","",IF(AND(G2>=Schedule!$G23,G2<=Schedule!$H23),"■","")) | H22: =IF(H2="","",IF(AND(H2>=Schedule!$G23,H2<=Schedule!$H23),"■","")) | I22: =IF(I2="","",IF(AND(I2>=Schedule!$G23,I2<=Schedule!$H23),"■","")) | J22: =IF(J2="","",IF(AND(J2>=Schedule!$G23,J2<=Schedule!$H23),"■","")) | ... EZ22: =IF(EZ2="","",IF(AND(EZ2>=Schedule!$G23,EZ2<=Schedule!$H23),"■",""))
A23: =Schedule!A24 -> 21 | B23: =Schedule!B24 -> 4 upper framing install | C23: =IF(C2="","",IF(AND(C2>=Schedule!$G24,C2<=Schedule!$H24),"■","")) | D23: =IF(D2="","",IF(AND(D2>=Schedule!$G24,D2<=Schedule!$H24),"■","")) | E23: =IF(E2="","",IF(AND(E2>=Schedule!$G24,E2<=Schedule!$H24),"■","")) | F23: =IF(F2="","",IF(AND(F2>=Schedule!$G24,F2<=Schedule!$H24),"■","")) | G23: =IF(G2="","",IF(AND(G2>=Schedule!$G24,G2<=Schedule!$H24),"■","")) | H23: =IF(H2="","",IF(AND(H2>=Schedule!$G24,H2<=Schedule!$H24),"■","")) | I23: =IF(I2="","",IF(AND(I2>=Schedule!$G24,I2<=Schedule!$H24),"■","")) | J23: =IF(J2="","",IF(AND(J2>=Schedule!$G24,J2<=Schedule!$H24),"■","")) | ... EZ23: =IF(EZ2="","",IF(AND(EZ2>=Schedule!$G24,EZ2<=Schedule!$H24),"■",""))
A24: =Schedule!A25 -> 22 | B24: =Schedule!B25 -> 4 lower roof truss install | C24: =IF(C2="","",IF(AND(C2>=Schedule!$G25,C2<=Schedule!$H25),"■","")) | D24: =IF(D2="","",IF(AND(D2>=Schedule!$G25,D2<=Schedule!$H25),"■","")) | E24: =IF(E2="","",IF(AND(E2>=Schedule!$G25,E2<=Schedule!$H25),"■","")) | F24: =IF(F2="","",IF(AND(F2>=Schedule!$G25,F2<=Schedule!$H25),"■","")) | G24: =IF(G2="","",IF(AND(G2>=Schedule!$G25,G2<=Schedule!$H25),"■","")) | H24: =IF(H2="","",IF(AND(H2>=Schedule!$G25,H2<=Schedule!$H25),"■","")) | I24: =IF(I2="","",IF(AND(I2>=Schedule!$G25,I2<=Schedule!$H25),"■","")) | J24: =IF(J2="","",IF(AND(J2>=Schedule!$G25,J2<=Schedule!$H25),"■","")) | ... EZ24: =IF(EZ2="","",IF(AND(EZ2>=Schedule!$G25,EZ2<=Schedule!$H25),"■",""))
A25: =Schedule!A26 -> 23 | B25: =Schedule!B26 -> 4 lower roof edge protection ? | C25: =IF(C2="","",IF(AND(C2>=Schedule!$G26,C2<=Schedule!$H26),"■","")) | D25: =IF(D2="","",IF(AND(D2>=Schedule!$G26,D2<=Schedule!$H26),"■","")) | E25: =IF(E2="","",IF(AND(E2>=Schedule!$G26,E2<=Schedule!$H26),"■","")) | F25: =IF(F2="","",IF(AND(F2>=Schedule!$G26,F2<=Schedule!$H26),"■","")) | G25: =IF(G2="","",IF(AND(G2>=Schedule!$G26,G2<=Schedule!$H26),"■","")) | H25: =IF(H2="","",IF(AND(H2>=Schedule!$G26,H2<=Schedule!$H26),"■","")) | I25: =IF(I2="","",IF(AND(I2>=Schedule!$G26,I2<=Schedule!$H26),"■","")) | J25: =IF(J2="","",IF(AND(J2>=Schedule!$G26,J2<=Schedule!$H26),"■","")) | ... EZ25: =IF(EZ2="","",IF(AND(EZ2>=Schedule!$G26,EZ2<=Schedule!$H26),"■",""))
A26: =Schedule!A27 -> 24 | B26: =Schedule!B27 -> 4 lower roof install | C26: =IF(C2="","",IF(AND(C2>=Schedule!$G27,C2<=Schedule!$H27),"■","")) | D26: =IF(D2="","",IF(AND(D2>=Schedule!$G27,D2<=Schedule!$H27),"■","")) | E26: =IF(E2="","",IF(AND(E2>=Schedule!$G27,E2<=Schedule!$H27),"■","")) | F26: =IF(F2="","",IF(AND(F2>=Schedule!$G27,F2<=Schedule!$H27),"■","")) | G26: =IF(G2="","",IF(AND(G2>=Schedule!$G27,G2<=Schedule!$H27),"■","")) | H26: =IF(H2="","",IF(AND(H2>=Schedule!$G27,H2<=Schedule!$H27),"■","")) | I26: =IF(I2="","",IF(AND(I2>=Schedule!$G27,I2<=Schedule!$H27),"■","")) | J26: =IF(J2="","",IF(AND(J2>=Schedule!$G27,J2<=Schedule!$H27),"■","")) | ... EZ26: =IF(EZ2="","",IF(AND(EZ2>=Schedule!$G27,EZ2<=Schedule!$H27),"■",""))
A27: =Schedule!A28 -> 25 | B27: =Schedule!B28 -> 4 scaffolding up | C27: =IF(C2="","",IF(AND(C2>=Schedule!$G28,C2<=Schedule!$H28),"■","")) | D27: =IF(D2="","",IF(AND(D2>=Schedule!$G28,D2<=Schedule!$H28),"■","")) | E27: =IF(E2="","",IF(AND(E2>=Schedule!$G28,E2<=Schedule!$H28),"■","")) | F27: =IF(F2="","",IF(AND(F2>=Schedule!$G28,F2<=Schedule!$H28),"■","")) | G27: =IF(G2="","",IF(AND(G2>=Schedule!$G28,G2<=Schedule!$H28),"■","")) | H27: =IF(H2="","",IF(AND(H2>=Schedule!$G28,H2<=Schedule!$H28),"■","")) | I27: =IF(I2="","",IF(AND(I2>=Schedule!$G28,I2<=Schedule!$H28),"■","")) | J27: =IF(J2="","",IF(AND(J2>=Schedule!$G28,J2<=Schedule!$H28),"■","")) | ... EZ27: =IF(EZ2="","",IF(AND(EZ2>=Schedule!$G28,EZ2<=Schedule!$H28),"■",""))
A28: =Schedule!A29 -> 26 | B28: =Schedule!B29 -> 4 upper roof truss delivery | C28: =IF(C2="","",IF(AND(C2>=Schedule!$G29,C2<=Schedule!$H29),"■","")) | D28: =IF(D2="","",IF(AND(D2>=Schedule!$G29,D2<=Schedule!$H29),"■","")) | E28: =IF(E2="","",IF(AND(E2>=Schedule!$G29,E2<=Schedule!$H29),"■","")) | F28: =IF(F2="","",IF(AND(F2>=Schedule!$G29,F2<=Schedule!$H29),"■","")) | G28: =IF(G2="","",IF(AND(G2>=Schedule!$G29,G2<=Schedule!$H29),"■","")) | H28: =IF(H2="","",IF(AND(H2>=Schedule!$G29,H2<=Schedule!$H29),"■","")) | I28: =IF(I2="","",IF(AND(I2>=Schedule!$G29,I2<=Schedule!$H29),"■","")) | J28: =IF(J2="","",IF(AND(J2>=Schedule!$G29,J2<=Schedule!$H29),"■","")) | ... EZ28: =IF(EZ2="","",IF(AND(EZ2>=Schedule!$G29,EZ2<=Schedule!$H29),"■",""))
A29: =Schedule!A30 -> 27 | B29: =Schedule!B30 -> 4 upper roof truss install | C29: =IF(C2="","",IF(AND(C2>=Schedule!$G30,C2<=Schedule!$H30),"■","")) | D29: =IF(D2="","",IF(AND(D2>=Schedule!$G30,D2<=Schedule!$H30),"■","")) | E29: =IF(E2="","",IF(AND(E2>=Schedule!$G30,E2<=Schedule!$H30),"■","")) | F29: =IF(F2="","",IF(AND(F2>=Schedule!$G30,F2<=Schedule!$H30),"■","")) | G29: =IF(G2="","",IF(AND(G2>=Schedule!$G30,G2<=Schedule!$H30),"■","")) | H29: =IF(H2="","",IF(AND(H2>=Schedule!$G30,H2<=Schedule!$H30),"■","")) | I29: =IF(I2="","",IF(AND(I2>=Schedule!$G30,I2<=Schedule!$H30),"■","")) | J29: =IF(J2="","",IF(AND(J2>=Schedule!$G30,J2<=Schedule!$H30),"■","")) | ... EZ29: =IF(EZ2="","",IF(AND(EZ2>=Schedule!$G30,EZ2<=Schedule!$H30),"■",""))
A30: =Schedule!A31 -> 28 | B30: =Schedule!B31 -> 4 upper roof edge protection （not required?) | C30: =IF(C2="","",IF(AND(C2>=Schedule!$G31,C2<=Schedule!$H31),"■","")) | D30: =IF(D2="","",IF(AND(D2>=Schedule!$G31,D2<=Schedule!$H31),"■","")) | E30: =IF(E2="","",IF(AND(E2>=Schedule!$G31,E2<=Schedule!$H31),"■","")) | F30: =IF(F2="","",IF(AND(F2>=Schedule!$G31,F2<=Schedule!$H31),"■","")) | G30: =IF(G2="","",IF(AND(G2>=Schedule!$G31,G2<=Schedule!$H31),"■","")) | H30: =IF(H2="","",IF(AND(H2>=Schedule!$G31,H2<=Schedule!$H31),"■","")) | I30: =IF(I2="","",IF(AND(I2>=Schedule!$G31,I2<=Schedule!$H31),"■","")) | J30: =IF(J2="","",IF(AND(J2>=Schedule!$G31,J2<=Schedule!$H31),"■","")) | ... EZ30: =IF(EZ2="","",IF(AND(EZ2>=Schedule!$G31,EZ2<=Schedule!$H31),"■",""))
A31: =Schedule!A32 -> 29 | B31: =Schedule!B32 -> 4 upper roof install | C31: =IF(C2="","",IF(AND(C2>=Schedule!$G32,C2<=Schedule!$H32),"■","")) | D31: =IF(D2="","",IF(AND(D2>=Schedule!$G32,D2<=Schedule!$H32),"■","")) | E31: =IF(E2="","",IF(AND(E2>=Schedule!$G32,E2<=Schedule!$H32),"■","")) | F31: =IF(F2="","",IF(AND(F2>=Schedule!$G32,F2<=Schedule!$H32),"■","")) | G31: =IF(G2="","",IF(AND(G2>=Schedule!$G32,G2<=Schedule!$H32),"■","")) | H31: =IF(H2="","",IF(AND(H2>=Schedule!$G32,H2<=Schedule!$H32),"■","")) | I31: =IF(I2="","",IF(AND(I2>=Schedule!$G32,I2<=Schedule!$H32),"■","")) | J31: =IF(J2="","",IF(AND(J2>=Schedule!$G32,J2<=Schedule!$H32),"■","")) | ... EZ31: =IF(EZ2="","",IF(AND(EZ2>=Schedule!$G32,EZ2<=Schedule!$H32),"■",""))
A32: =Schedule!A33 -> 30 | B32: =Schedule!B33 -> 4 electrical roughin | C32: =IF(C2="","",IF(AND(C2>=Schedule!$G33,C2<=Schedule!$H33),"■","")) | D32: =IF(D2="","",IF(AND(D2>=Schedule!$G33,D2<=Schedule!$H33),"■","")) | E32: =IF(E2="","",IF(AND(E2>=Schedule!$G33,E2<=Schedule!$H33),"■","")) | F32: =IF(F2="","",IF(AND(F2>=Schedule!$G33,F2<=Schedule!$H33),"■","")) | G32: =IF(G2="","",IF(AND(G2>=Schedule!$G33,G2<=Schedule!$H33),"■","")) | H32: =IF(H2="","",IF(AND(H2>=Schedule!$G33,H2<=Schedule!$H33),"■","")) | I32: =IF(I2="","",IF(AND(I2>=Schedule!$G33,I2<=Schedule!$H33),"■","")) | J32: =IF(J2="","",IF(AND(J2>=Schedule!$G33,J2<=Schedule!$H33),"■","")) | ... EZ32: =IF(EZ2="","",IF(AND(EZ2>=Schedule!$G33,EZ2<=Schedule!$H33),"■",""))
A33: =Schedule!A34 -> 31 | B33: =Schedule!B34 -> 4 AC roughin | C33: =IF(C2="","",IF(AND(C2>=Schedule!$G34,C2<=Schedule!$H34),"■","")) | D33: =IF(D2="","",IF(AND(D2>=Schedule!$G34,D2<=Schedule!$H34),"■","")) | E33: =IF(E2="","",IF(AND(E2>=Schedule!$G34,E2<=Schedule!$H34),"■","")) | F33: =IF(F2="","",IF(AND(F2>=Schedule!$G34,F2<=Schedule!$H34),"■","")) | G33: =IF(G2="","",IF(AND(G2>=Schedule!$G34,G2<=Schedule!$H34),"■","")) | H33: =IF(H2="","",IF(AND(H2>=Schedule!$G34,H2<=Schedule!$H34),"■","")) | I33: =IF(I2="","",IF(AND(I2>=Schedule!$G34,I2<=Schedule!$H34),"■","")) | J33: =IF(J2="","",IF(AND(J2>=Schedule!$G34,J2<=Schedule!$H34),"■","")) | ... EZ33: =IF(EZ2="","",IF(AND(EZ2>=Schedule!$G34,EZ2<=Schedule!$H34),"■",""))
A34: =Schedule!A35 -> 32 | B34: =Schedule!B35 -> 4 plumbing roughin | C34: =IF(C2="","",IF(AND(C2>=Schedule!$G35,C2<=Schedule!$H35),"■","")) | D34: =IF(D2="","",IF(AND(D2>=Schedule!$G35,D2<=Schedule!$H35),"■","")) | E34: =IF(E2="","",IF(AND(E2>=Schedule!$G35,E2<=Schedule!$H35),"■","")) | F34: =IF(F2="","",IF(AND(F2>=Schedule!$G35,F2<=Schedule!$H35),"■","")) | G34: =IF(G2="","",IF(AND(G2>=Schedule!$G35,G2<=Schedule!$H35),"■","")) | H34: =IF(H2="","",IF(AND(H2>=Schedule!$G35,H2<=Schedule!$H35),"■","")) | I34: =IF(I2="","",IF(AND(I2>=Schedule!$G35,I2<=Schedule!$H35),"■","")) | J34: =IF(J2="","",IF(AND(J2>=Schedule!$G35,J2<=Schedule!$H35),"■","")) | ... EZ34: =IF(EZ2="","",IF(AND(EZ2>=Schedule!$G35,EZ2<=Schedule!$H35),"■",""))
A35: =Schedule!A36 -> 33 | B35: =Schedule!B36 -> 4 wall wrap | C35: =IF(C2="","",IF(AND(C2>=Schedule!$G36,C2<=Schedule!$H36),"■","")) | D35: =IF(D2="","",IF(AND(D2>=Schedule!$G36,D2<=Schedule!$H36),"■","")) | E35: =IF(E2="","",IF(AND(E2>=Schedule!$G36,E2<=Schedule!$H36),"■","")) | F35: =IF(F2="","",IF(AND(F2>=Schedule!$G36,F2<=Schedule!$H36),"■","")) | G35: =IF(G2="","",IF(AND(G2>=Schedule!$G36,G2<=Schedule!$H36),"■","")) | H35: =IF(H2="","",IF(AND(H2>=Schedule!$G36,H2<=Schedule!$H36),"■","")) | I35: =IF(I2="","",IF(AND(I2>=Schedule!$G36,I2<=Schedule!$H36),"■","")) | J35: =IF(J2="","",IF(AND(J2>=Schedule!$G36,J2<=Schedule!$H36),"■","")) | ... EZ35: =IF(EZ2="","",IF(AND(EZ2>=Schedule!$G36,EZ2<=Schedule!$H36),"■",""))
A36: =Schedule!A37 -> 34 | B36: =Schedule!B37 -> 4 framing inspection | C36: =IF(C2="","",IF(AND(C2>=Schedule!$G37,C2<=Schedule!$H37),"■","")) | D36: =IF(D2="","",IF(AND(D2>=Schedule!$G37,D2<=Schedule!$H37),"■","")) | E36: =IF(E2="","",IF(AND(E2>=Schedule!$G37,E2<=Schedule!$H37),"■","")) | F36: =IF(F2="","",IF(AND(F2>=Schedule!$G37,F2<=Schedule!$H37),"■","")) | G36: =IF(G2="","",IF(AND(G2>=Schedule!$G37,G2<=Schedule!$H37),"■","")) | H36: =IF(H2="","",IF(AND(H2>=Schedule!$G37,H2<=Schedule!$H37),"■","")) | I36: =IF(I2="","",IF(AND(I2>=Schedule!$G37,I2<=Schedule!$H37),"■","")) | J36: =IF(J2="","",IF(AND(J2>=Schedule!$G37,J2<=Schedule!$H37),"■","")) | ... EZ36: =IF(EZ2="","",IF(AND(EZ2>=Schedule!$G37,EZ2<=Schedule!$H37),"■",""))
A37: =Schedule!A38 -> 35 | B37: =Schedule!B38 -> 4 windows delivery | C37: =IF(C2="","",IF(AND(C2>=Schedule!$G38,C2<=Schedule!$H38),"■","")) | D37: =IF(D2="","",IF(AND(D2>=Schedule!$G38,D2<=Schedule!$H38),"■","")) | E37: =IF(E2="","",IF(AND(E2>=Schedule!$G38,E2<=Schedule!$H38),"■","")) | F37: =IF(F2="","",IF(AND(F2>=Schedule!$G38,F2<=Schedule!$H38),"■","")) | G37: =IF(G2="","",IF(AND(G2>=Schedule!$G38,G2<=Schedule!$H38),"■","")) | H37: =IF(H2="","",IF(AND(H2>=Schedule!$G38,H2<=Schedule!$H38),"■","")) | I37: =IF(I2="","",IF(AND(I2>=Schedule!$G38,I2<=Schedule!$H38),"■","")) | J37: =IF(J2="","",IF(AND(J2>=Schedule!$G38,J2<=Schedule!$H38),"■","")) | ... EZ37: =IF(EZ2="","",IF(AND(EZ2>=Schedule!$G38,EZ2<=Schedule!$H38),"■",""))
A38: =Schedule!A39 -> 36 | B38: =Schedule!B39 -> 4 entry doors delivery | C38: =IF(C2="","",IF(AND(C2>=Schedule!$G39,C2<=Schedule!$H39),"■","")) | D38: =IF(D2="","",IF(AND(D2>=Schedule!$G39,D2<=Schedule!$H39),"■","")) | E38: =IF(E2="","",IF(AND(E2>=Schedule!$G39,E2<=Schedule!$H39),"■","")) | F38: =IF(F2="","",IF(AND(F2>=Schedule!$G39,F2<=Schedule!$H39),"■","")) | G38: =IF(G2="","",IF(AND(G2>=Schedule!$G39,G2<=Schedule!$H39),"■","")) | H38: =IF(H2="","",IF(AND(H2>=Schedule!$G39,H2<=Schedule!$H39),"■","")) | I38: =IF(I2="","",IF(AND(I2>=Schedule!$G39,I2<=Schedule!$H39),"■","")) | J38: =IF(J2="","",IF(AND(J2>=Schedule!$G39,J2<=Schedule!$H39),"■","")) | ... EZ38: =IF(EZ2="","",IF(AND(EZ2>=Schedule!$G39,EZ2<=Schedule!$H39),"■",""))
A39: =Schedule!A40 -> 37 | B39: =Schedule!B40 -> 4 lockup labour | C39: =IF(C2="","",IF(AND(C2>=Schedule!$G40,C2<=Schedule!$H40),"■","")) | D39: =IF(D2="","",IF(AND(D2>=Schedule!$G40,D2<=Schedule!$H40),"■","")) | E39: =IF(E2="","",IF(AND(E2>=Schedule!$G40,E2<=Schedule!$H40),"■","")) | F39: =IF(F2="","",IF(AND(F2>=Schedule!$G40,F2<=Schedule!$H40),"■","")) | G39: =IF(G2="","",IF(AND(G2>=Schedule!$G40,G2<=Schedule!$H40),"■","")) | H39: =IF(H2="","",IF(AND(H2>=Schedule!$G40,H2<=Schedule!$H40),"■","")) | I39: =IF(I2="","",IF(AND(I2>=Schedule!$G40,I2<=Schedule!$H40),"■","")) | J39: =IF(J2="","",IF(AND(J2>=Schedule!$G40,J2<=Schedule!$H40),"■","")) | ... EZ39: =IF(EZ2="","",IF(AND(EZ2>=Schedule!$G40,EZ2<=Schedule!$H40),"■",""))
A40: =Schedule!A41 -> 38 | B40: =Schedule!B41 -> 4 staircase supply&install | C40: =IF(C2="","",IF(AND(C2>=Schedule!$G41,C2<=Schedule!$H41),"■","")) | D40: =IF(D2="","",IF(AND(D2>=Schedule!$G41,D2<=Schedule!$H41),"■","")) | E40: =IF(E2="","",IF(AND(E2>=Schedule!$G41,E2<=Schedule!$H41),"■","")) | F40: =IF(F2="","",IF(AND(F2>=Schedule!$G41,F2<=Schedule!$H41),"■","")) | G40: =IF(G2="","",IF(AND(G2>=Schedule!$G41,G2<=Schedule!$H41),"■","")) | H40: =IF(H2="","",IF(AND(H2>=Schedule!$G41,H2<=Schedule!$H41),"■","")) | I40: =IF(I2="","",IF(AND(I2>=Schedule!$G41,I2<=Schedule!$H41),"■","")) | J40: =IF(J2="","",IF(AND(J2>=Schedule!$G41,J2<=Schedule!$H41),"■","")) | ... EZ40: =IF(EZ2="","",IF(AND(EZ2>=Schedule!$G41,EZ2<=Schedule!$H41),"■",""))
...
